{
  "comments": [
    {
      "unresolved": false,
      "key": {
        "uuid": "cc3be171_e92412fb",
        "filename": "/PATCHSET_LEVEL",
        "patchSetId": 17
      },
      "lineNbr": 0,
      "author": {
        "id": 1000248
      },
      "writtenOn": "2024-04-04T17:30:06Z",
      "side": 1,
      "message": "I\u0027ve resolved all feedback and I believe this is ready to merge if there\u0027s nothing further.",
      "revId": "684579396cc66a35a4f58393a9b048d1fac37550",
      "serverId": "dd02978d-1a8e-36d7-bcc0-a5723e5c0abd"
    },
    {
      "unresolved": false,
      "key": {
        "uuid": "08e4e05b_3900ad56",
        "filename": "/PATCHSET_LEVEL",
        "patchSetId": 17
      },
      "lineNbr": 0,
      "author": {
        "id": 1000248
      },
      "writtenOn": "2024-04-04T20:59:59Z",
      "side": 1,
      "message": "I\u0027m seeing a failure on the bots, which I can\u0027t explain. The test and code has passed many times before and is passing locally. Investigating.",
      "parentUuid": "cc3be171_e92412fb",
      "revId": "684579396cc66a35a4f58393a9b048d1fac37550",
      "serverId": "dd02978d-1a8e-36d7-bcc0-a5723e5c0abd"
    }
  ]
}