{
  "comments": [
    {
      "unresolved": false,
      "key": {
        "uuid": "5c29aef4_38aca04c",
        "filename": "/PATCHSET_LEVEL",
        "patchSetId": 8
      },
      "lineNbr": 0,
      "author": {
        "id": 1000024
      },
      "writtenOn": "2023-12-11T14:59:56Z",
      "side": 1,
      "message": "Austin, Brandon: I\u0027ve suppressed all the Pixel 4 e2e test failures, but the bot is still failing on what seem to be timeouts. Could use some help diagnosing. Thanks!",
      "revId": "99d733011453a93deefeb332e237cee5822eb634",
      "serverId": "dd02978d-1a8e-36d7-bcc0-a5723e5c0abd"
    },
    {
      "unresolved": false,
      "key": {
        "uuid": "571672d9_c4f1c4ef",
        "filename": "/PATCHSET_LEVEL",
        "patchSetId": 8
      },
      "lineNbr": 0,
      "author": {
        "id": 1000024
      },
      "writtenOn": "2023-12-11T15:00:30Z",
      "side": 1,
      "message": "(Will add some bug IDs for the failures before landing.)",
      "revId": "99d733011453a93deefeb332e237cee5822eb634",
      "serverId": "dd02978d-1a8e-36d7-bcc0-a5723e5c0abd"
    },
    {
      "unresolved": false,
      "key": {
        "uuid": "ac2deeba_2a90809e",
        "filename": "/PATCHSET_LEVEL",
        "patchSetId": 8
      },
      "lineNbr": 0,
      "author": {
        "id": 1000024
      },
      "writtenOn": "2023-12-11T16:22:22Z",
      "side": 1,
      "message": "Timing out while searching for crash symbols, maybe? +bsheedy in case this is a Telemetry issue.",
      "revId": "99d733011453a93deefeb332e237cee5822eb634",
      "serverId": "dd02978d-1a8e-36d7-bcc0-a5723e5c0abd"
    },
    {
      "unresolved": false,
      "key": {
        "uuid": "d92958c5_7bf9f89b",
        "filename": "/PATCHSET_LEVEL",
        "patchSetId": 8
      },
      "lineNbr": 0,
      "author": {
        "id": 1001591
      },
      "writtenOn": "2023-12-11T16:49:45Z",
      "side": 1,
      "message": "ðŸŽ¶ Hello Qualcomm, my old friend\nI\u0027ve come to Blocklist you again\nBecause of errors you left creeping\nInto the textures I was keeping... ðŸŽµ\n\nLGTM. ðŸ˜Š",
      "revId": "99d733011453a93deefeb332e237cee5822eb634",
      "serverId": "dd02978d-1a8e-36d7-bcc0-a5723e5c0abd"
    },
    {
      "unresolved": true,
      "key": {
        "uuid": "4237ad56_6c95777c",
        "filename": "/PATCHSET_LEVEL",
        "patchSetId": 8
      },
      "lineNbr": 0,
      "author": {
        "id": 1000032
      },
      "writtenOn": "2023-12-11T20:11:37Z",
      "side": 1,
      "message": "it kind of looks like it\u0027s failing to upload results?\n\n[I2023-12-05T21:26:32.064380Z 9127 0 sink_server.go:95] SinkServer: draining TestResult channel started\nI 21:26:32.066 1806.051s Main  Finishing archiving output.\nE 21:26:32.066 1806.051s Main  Unrecognized error occurred.\nTraceback (most recent call last):\n  File \"../../build/android/test_runner.py\", line 1048, in json_writer\n    yield\n  File \"../../build/android/test_runner.py\", line 1152, in RunTestsInPlatformMode\n    test_run.RunTests(raw_results, raw_logs_fh\u003draw_logs_fh)\n  File \"/b/swarming/w/ir/build/android/pylib/local/device/local_device_test_run.py\", line 190, in RunTests\n    self._env.parallel_devices.pMap(\n  File \"/b/swarming/w/ir/third_party/catapult/devil/devil/utils/parallelizer.py\", line 265, in pMap\n    r.pFinish(None)\n  File \"/b/swarming/w/ir/third_party/catapult/devil/devil/utils/parallelizer.py\", line 134, in pFinish\n    self._objs.JoinAll()\n  File \"/b/swarming/w/ir/third_party/catapult/devil/devil/utils/reraiser_thread.py\", line 234, in JoinAll\n    self._JoinAll(watcher, timeout)\n  File \"/b/swarming/w/ir/third_party/catapult/devil/devil/utils/reraiser_thread.py\", line 201, in _JoinAll\n    thread.join(0.1)\n  File \"/b/swarming/w/ir/.task_template_vpython_cache/vpython/store/cpython+kp5sf4ggj3quhveqf2mb3pane0/contents/lib/python3.8/threading.py\", line 1015, in join\n    self._wait_for_tstate_lock(timeout\u003dmax(timeout, 0))\n  File \"/b/swarming/w/ir/.task_template_vpython_cache/vpython/store/cpython+kp5sf4ggj3quhveqf2mb3pane0/contents/lib/python3.8/threading.py\", line 1027, in _wait_for_tstate_lock\n    elif lock.acquire(block, timeout):\n  File \"/b/swarming/w/ir/third_party/catapult/devil/devil/utils/signal_handler.py\", line 41, in handler\n    existing_handler(signum, frame)\n  File \"../../build/android/test_runner.py\", line 1009, in unexpected_sigterm\n    infra_error(\u0027\\n\u0027.join(msg))\n  File \"../../build/android/test_runner.py\", line 985, in infra_error\n    sys.exit(constants.INFRA_EXIT_CODE)\nSystemExit: 87\n\nDuring handling of the above exception, another exception occurred:\n\nTraceback (most recent call last):\n  File \"/b/swarming/w/ir/.task_template_vpython_cache/vpython/store/python_venv-0jvolg2548flk4vlvvj2vf6dbg/contents/lib/python3.8/site-packages/urllib3/connection.py\", line 169, in _new_conn\n    conn \u003d connection.create_connection(\n  File \"/b/swarming/w/ir/.task_template_vpython_cache/vpython/store/python_venv-0jvolg2548flk4vlvvj2vf6dbg/contents/lib/python3.8/site-packages/urllib3/util/connection.py\", line 96, in create_connection\n    raise err\n  File \"/b/swarming/w/ir/.task_template_vpython_cache/vpython/store/python_venv-0jvolg2548flk4vlvvj2vf6dbg/contents/lib/python3.8/site-packages/urllib3/util/connection.py\", line 86, in create_connection\n    sock.connect(sa)\nConnectionRefusedError: [Errno 111] Connection refused\n\nDuring handling of the above exception, another exception occurred:\n\nTraceback (most recent call last):\n  File \"/b/swarming/w/ir/.task_template_vpython_cache/vpython/store/python_venv-0jvolg2548flk4vlvvj2vf6dbg/contents/lib/python3.8/site-packages/urllib3/connectionpool.py\", line 699, in urlopen\n    httplib_response \u003d self._make_request(\n  File \"/b/swarming/w/ir/.task_template_vpython_cache/vpython/store/python_venv-0jvolg2548flk4vlvvj2vf6dbg/contents/lib/python3.8/site-packages/urllib3/connectionpool.py\", line 394, in _make_request\n    conn.request(method, url, **httplib_request_kw)\n  File \"/b/swarming/w/ir/.task_template_vpython_cache/vpython/store/python_venv-0jvolg2548flk4vlvvj2vf6dbg/contents/lib/python3.8/site-packages/urllib3/connection.py\", line 234, in request\n    super(HTTPConnection, self).request(method, url, body\u003dbody, headers\u003dheaders)\n  File \"/b/swarming/w/ir/.task_template_vpython_cache/vpython/store/cpython+kp5sf4ggj3quhveqf2mb3pane0/contents/lib/python3.8/http/client.py\", line 1252, in request\n    self._send_request(method, url, body, headers, encode_chunked)\n  File \"/b/swarming/w/ir/.task_template_vpython_cache/vpython/store/cpython+kp5sf4ggj3quhveqf2mb3pane0/contents/lib/python3.8/http/client.py\", line 1298, in _send_request\n    self.endheaders(body, encode_chunked\u003dencode_chunked)\n  File \"/b/swarming/w/ir/.task_template_vpython_cache/vpython/store/cpython+kp5sf4ggj3quhveqf2mb3pane0/contents/lib/python3.8/http/client.py\", line 1247, in endheaders\n    self._send_output(message_body, encode_chunked\u003dencode_chunked)\n  File \"/b/swarming/w/ir/.task_template_vpython_cache/vpython/store/cpython+kp5sf4ggj3quhveqf2mb3pane0/contents/lib/python3.8/http/client.py\", line 1007, in _send_output\n    self.send(msg)\n  File \"/b/swarming/w/ir/.task_template_vpython_cache/vpython/store/cpython+kp5sf4ggj3quhveqf2mb3pane0/contents/lib/python3.8/http/client.py\", line 947, in send\n    self.connect()\n  File \"/b/swarming/w/ir/.task_template_vpython_cache/vpython/store/python_venv-0jvolg2548flk4vlvvj2vf6dbg/contents/lib/python3.8/site-packages/urllib3/connection.py\", line 200, in connect\n    conn \u003d self._new_conn()\n  File \"/b/swarming/w/ir/.task_template_vpython_cache/vpython/store/python_venv-0jvolg2548flk4vlvvj2vf6dbg/contents/lib/python3.8/site-packages/urllib3/connection.py\", line 181, in _new_conn\n    raise NewConnectionError(\nurllib3.exceptions.NewConnectionError: \u003curllib3.connection.HTTPConnection object at 0x7f0f09da3400\u003e: Failed to establish a new connection: [Errno 111] Connection refused\n\nDuring handling of the above exception, another exception occurred:\n\nTraceback (most recent call last):\n  File \"/b/swarming/w/ir/.task_template_vpython_cache/vpython/store/python_venv-0jvolg2548flk4vlvvj2vf6dbg/contents/lib/python3.8/site-packages/requests/adapters.py\", line 486, in send\n    resp \u003d conn.urlopen(\n  File \"/b/swarming/w/ir/.task_template_vpython_cache/vpython/store/python_venv-0jvolg2548flk4vlvvj2vf6dbg/contents/lib/python3.8/site-packages/urllib3/connectionpool.py\", line 755, in urlopen\n    retries \u003d retries.increment(\n  File \"/b/swarming/w/ir/.task_template_vpython_cache/vpython/store/python_venv-0jvolg2548flk4vlvvj2vf6dbg/contents/lib/python3.8/site-packages/urllib3/util/retry.py\", line 574, in increment\n    raise MaxRetryError(_pool, url, error or ResponseError(cause))\nurllib3.exceptions.MaxRetryError: HTTPConnectionPool(host\u003d\u0027localhost\u0027, port\u003d40087): Max retries exceeded with url: /prpc/luci.resultsink.v1.Sink/ReportTestResults (Caused by NewConnectionError(\u0027\u003curllib3.connection.HTTPConnection object at 0x7f0f09da3400\u003e: Failed to establish a new connection: [Errno 111] Connection refused\u0027))\n\nDuring handling of the above exception, another exception occurred:\n\nTraceback (most recent call last):\n  File \"../../build/android/test_runner.py\", line 1407, in main\n    return RunTestsCommand(args, result_sink_client)\n  File \"../../build/android/test_runner.py\", line 927, in RunTestsCommand\n    return RunTestsInPlatformMode(args, result_sink_client)\n  File \"../../build/android/test_runner.py\", line 1202, in RunTestsInPlatformMode\n    logging.critical(\u0027%s of %s tests passed in all %s runs\u0027,\n  File \"/b/swarming/w/ir/.task_template_vpython_cache/vpython/store/cpython+kp5sf4ggj3quhveqf2mb3pane0/contents/lib/python3.8/contextlib.py\", line 131, in __exit__\n    self.gen.throw(type, value, traceback)\n  File \"../../build/android/test_runner.py\", line 1080, in json_writer\n    _SinkTestResult(r, test_file_name, result_sink_client)\n  File \"../../build/android/test_runner.py\", line 961, in _SinkTestResult\n    result_sink_client.Post(test_result.GetNameForResultSink(),\n  File \"/b/swarming/w/ir/build/util/lib/results/result_sink.py\", line 187, in Post\n    res \u003d self.session.post(url\u003dself.test_results_url,\n  File \"/b/swarming/w/ir/.task_template_vpython_cache/vpython/store/python_venv-0jvolg2548flk4vlvvj2vf6dbg/contents/lib/python3.8/site-packages/requests/sessions.py\", line 637, in post\n    return self.request(\"POST\", url, data\u003ddata, json\u003djson, **kwargs)\n  File \"/b/swarming/w/ir/.task_template_vpython_cache/vpython/store/python_venv-0jvolg2548flk4vlvvj2vf6dbg/contents/lib/python3.8/site-packages/requests/sessions.py\", line 589, in request\n    resp \u003d self.send(prep, **send_kwargs)\n  File \"/b/swarming/w/ir/.task_template_vpython_cache/vpython/store/python_venv-0jvolg2548flk4vlvvj2vf6dbg/contents/lib/python3.8/site-packages/requests/sessions.py\", line 703, in send\n    r \u003d adapter.send(request, **kwargs)\n  File \"/b/swarming/w/ir/.task_template_vpython_cache/vpython/store/python_venv-0jvolg2548flk4vlvvj2vf6dbg/contents/lib/python3.8/site-packages/requests/adapters.py\", line 519, in send\n    raise ConnectionError(e, request\u003drequest)\nrequests.exceptions.ConnectionError: HTTPConnectionPool(host\u003d\u0027localhost\u0027, port\u003d40087): Max retries exceeded with url: /prpc/luci.resultsink.v1.Sink/ReportTestResults (Caused by NewConnectionError(\u0027\u003curllib3.connection.HTTPConnection object at 0x7f0f09da3400\u003e: Failed to establish a new connection: [Errno 111] Connection refused\u0027))\nForwarding signal(15) to process 9170\nForwarding signal(15) to process 9169\n[I2023-12-05T21:26:32.256449Z 9127 0 sink_server.go:97] SinkServer: draining TestResult channel ended\n[I2023-12-05T21:26:32.256489Z 9127 0 sink_server.go:99] SinkServer: draining Artifact channel started\n[I2023-12-05T21:26:32.550193Z 9127 0 sink_server.go:101] SinkServer: draining Artifact channel ended\n[I2023-12-05T21:26:32.550234Z 9127 0 sink_server.go:104] SinkServer: draining TestExoneration channel started\n[I2023-12-05T21:26:32.550255Z 9127 0 sink_server.go:106] SinkServer: draining TestExoneration channel ended\n[I2023-12-05T21:26:32.550270Z 9127 0 sink.go:374] SinkServer: shutdown completed successfully\n[I2023-12-05T21:26:32.550284Z 9127 0 cmd_stream.go:401] rdb-stream: exiting with -1",
      "parentUuid": "5c29aef4_38aca04c",
      "revId": "99d733011453a93deefeb332e237cee5822eb634",
      "serverId": "dd02978d-1a8e-36d7-bcc0-a5723e5c0abd"
    },
    {
      "unresolved": true,
      "key": {
        "uuid": "4a7e7752_f899917f",
        "filename": "/PATCHSET_LEVEL",
        "patchSetId": 8
      },
      "lineNbr": 0,
      "author": {
        "id": 1000024
      },
      "writtenOn": "2023-12-12T17:07:09Z",
      "side": 1,
      "message": "Good point. This looks problematic:\n\nurllib3.exceptions.NewConnectionError: \u003curllib3.connection.HTTPConnection object at 0x7f0f09da3400\u003e: Failed to establish a new connection: [Errno 111] Connection refused",
      "parentUuid": "4237ad56_6c95777c",
      "revId": "99d733011453a93deefeb332e237cee5822eb634",
      "serverId": "dd02978d-1a8e-36d7-bcc0-a5723e5c0abd"
    },
    {
      "unresolved": false,
      "key": {
        "uuid": "51b78075_5625a56a",
        "filename": "/PATCHSET_LEVEL",
        "patchSetId": 8
      },
      "lineNbr": 0,
      "author": {
        "id": 1000024
      },
      "writtenOn": "2023-12-18T04:04:56Z",
      "side": 1,
      "message": "This seems to be fixed now. Thanks Brian and Yuly!",
      "parentUuid": "4a7e7752_f899917f",
      "revId": "99d733011453a93deefeb332e237cee5822eb634",
      "serverId": "dd02978d-1a8e-36d7-bcc0-a5723e5c0abd"
    },
    {
      "unresolved": true,
      "key": {
        "uuid": "91dcb153_dac5c655",
        "filename": "src/dawn/tests/end2end/BufferZeroInitTests.cpp",
        "patchSetId": 8
      },
      "lineNbr": 942,
      "author": {
        "id": 1001591
      },
      "writtenOn": "2023-12-11T16:49:45Z",
      "side": 1,
      "message": "It would be great if we had at least an umbrella bug in a //TODO to associate all these suppressions with, even if they\u0027re not all assumed to have the same root cause.",
      "revId": "99d733011453a93deefeb332e237cee5822eb634",
      "serverId": "dd02978d-1a8e-36d7-bcc0-a5723e5c0abd"
    },
    {
      "unresolved": true,
      "key": {
        "uuid": "8f1ee104_6667e873",
        "filename": "src/dawn/tests/end2end/BufferZeroInitTests.cpp",
        "patchSetId": 8
      },
      "lineNbr": 942,
      "author": {
        "id": 1000024
      },
      "writtenOn": "2023-12-11T17:10:38Z",
      "side": 1,
      "message": "Will do (see above comment). Just looking for help with the timeout issue.\n\nLooks like it runs a group of tests in 1-2sec, then spends 30-60 sec looking for crashes. Lather, rinse, repeat until 30 min timeout for the step. AFAICT.",
      "parentUuid": "91dcb153_dac5c655",
      "revId": "99d733011453a93deefeb332e237cee5822eb634",
      "serverId": "dd02978d-1a8e-36d7-bcc0-a5723e5c0abd"
    },
    {
      "unresolved": false,
      "key": {
        "uuid": "5f8d0db9_53e124bb",
        "filename": "src/dawn/tests/end2end/BufferZeroInitTests.cpp",
        "patchSetId": 8
      },
      "lineNbr": 942,
      "author": {
        "id": 1000024
      },
      "writtenOn": "2023-12-18T04:04:56Z",
      "side": 1,
      "message": "Done",
      "parentUuid": "8f1ee104_6667e873",
      "revId": "99d733011453a93deefeb332e237cee5822eb634",
      "serverId": "dd02978d-1a8e-36d7-bcc0-a5723e5c0abd"
    }
  ]
}